<robot name="xhand_right">
  <link name="right_hand_link">
    <inertial>
      <origin xyz="-0.00366836214548078 0.0100351220466308 -0.0582695185384578" rpy="0 0 0" />
      <mass value="0.53903004" />
      <inertia ixx="0.00046462" ixy="0.00000004" ixz="-0.00005128" iyy="0.00064214" iyz="0.00000217" izz="0.00027541" />
    </inertial>
    <visual>
      <origin xyz="0 0 0" rpy="0 0 0" />
      <geometry>
        <mesh filename="../meshes/right_hand_link.STL" />
      </geometry>
      <material name="RAL_9005_Jet_Black">
        <color rgba="0.055 0.055 0.063 1.0" />
      </material>
    </visual>
    <collision>
      <origin xyz="0 0 0" rpy="0 0 0" />
      <geometry>
        <mesh filename="../meshes/right_hand_link.STL" />
      </geometry>
    </collision>
  </link>
  <link name="right_hand_ee_link">
    <visual>
      <origin xyz="0 0 0" rpy="0 0 0" />
      <geometry>
        <mesh filename="../meshes/right_hand_ee_link.STL" />
      </geometry>
      <material name="RAL_9005_Jet_Black">
        <color rgba="0.055 0.055 0.063 1.0" />
      </material>
    </visual>
    <collision>
      <origin xyz="0 0 0" rpy="0 0 0" />
      <geometry>
        <mesh filename="../meshes/right_hand_ee_link.STL" />
      </geometry>
    </collision>
  <inertial><origin xyz="0 0 0" rpy="0 0 0" /><mass value="0.01" /><inertia ixx="1e-5" iyy="1e-5" izz="1e-5" ixy="0" ixz="0" iyz="0" /></inertial></link>
  <joint name="right_hand_ee_joint" type="fixed">
    <origin xyz="0 0 -0.065" rpy="0 0 0" />
    <parent link="right_hand_link" />
    <child link="right_hand_ee_link" />
    <axis xyz="0 0 0" />
    <dynamics damping="0" friction="0" />
  </joint>
  <link name="right_hand_back_link">
    <visual>
      <origin xyz="0 0 0" rpy="0 0 0" />
      <geometry>
        <mesh filename="../meshes/right_hand_back_link.STL" />
      </geometry>
      <material name="RAL_9003_Signal_White">
        <color rgba="0.941 0.941 0.941 1.0" />
      </material>
    </visual>
    <collision>
      <origin xyz="0 0 0" rpy="0 0 0" />
      <geometry>
        <mesh filename="../meshes/right_hand_back_link.STL" />
      </geometry>
    </collision>
  <inertial><origin xyz="0 0 0" rpy="0 0 0" /><mass value="0.01" /><inertia ixx="1e-5" iyy="1e-5" izz="1e-5" ixy="0" ixz="0" iyz="0" /></inertial></link>
  <joint name="right_hand_back_joint" type="fixed">
    <origin xyz="0 0 -0.065" rpy="0 0 0" />
    <parent link="right_hand_link" />
    <child link="right_hand_back_link" />
    <axis xyz="0 0 0" />
    <dynamics damping="0" friction="0" />
  </joint>
  <link name="right_hand_thumb_bend_link">
    <inertial>
      <origin xyz="0.0144358799903648 -0.00116534489100676 -5.40665183231849E-05" rpy="0 0 0" />
      <mass value="0.01174632" />
      <inertia ixx="0.00000062" ixy="-0.00000004" ixz="-0.00000007" iyy="0.0000016" iyz="0.00000000001" izz="0.00000162" />
    </inertial>
    <visual>
      <origin xyz="0 0 0" rpy="0 0 0" />
      <geometry>
        <mesh filename="../meshes/right_hand_thumb_bend_link.STL" />
      </geometry>
      <material name="RAL_9005_Jet_Black">
        <color rgba="0.055 0.055 0.063 1.0" />
      </material>
    </visual>
    <collision>
      <origin xyz="0 0 0" rpy="0 0 0" />
      <geometry>
        <mesh filename="../meshes/right_hand_thumb_bend_link.STL" />
      </geometry>
    </collision>
  </link>
  <joint name="right_hand_thumb_bend_joint" type="revolute">
    <origin xyz="0.0228 0.0095 -0.0305" rpy="0 0 0" />
    <parent link="right_hand_link" />
    <child link="right_hand_thumb_bend_link" />
    <axis xyz="0 0 1" />
    <limit lower="0" upper="1.832" effort="1.1" velocity="8.63" />
    <dynamics damping="0" friction="0" />
  </joint>
  <link name="right_hand_thumb_rota_link1">
    <inertial>
      <origin xyz="0.0287681482733488 -0.00036176529547633 -0.00133929681686046" rpy="0 0 0" />
      <mass value="0.13266642" />
      <inertia ixx="0.00001699" ixy="-0.00000791" ixz="-0.00000182" iyy="0.00003679" iyz="-0.00000196" izz="0.00004374" />
    </inertial>
    <visual>
      <origin xyz="0 0 0" rpy="0 0 0" />
      <geometry>
        <mesh filename="../meshes/right_hand_thumb_rota_link1.STL" />
      </geometry>
      <material name="RAL_9005_Jet_Black">
        <color rgba="0.055 0.055 0.063 1.0" />
      </material>
    </visual>
    <collision>
      <origin xyz="0 0 0" rpy="0 0 0" />
      <geometry>
        <mesh filename="../meshes/right_hand_thumb_rota_link1.STL" />
      </geometry>
    </collision>
  </link>
  <joint name="right_hand_thumb_rota_joint1" type="revolute">
    <origin xyz="0.028599 0.0083177 0.00178" rpy="0.2618 0 0.0407" />
    <parent link="right_hand_thumb_bend_link" />
    <child link="right_hand_thumb_rota_link1" />
    <axis xyz="0 1 0" />
    <limit lower="-0.698" upper="1.745" effort="1.1" velocity="8.63" />
    <dynamics damping="0" friction="0" />
  </joint>
  <link name="right_hand_thumb_rotaback_link1">
    <visual>
      <origin xyz="0 0 0" rpy="0 0 0" />
      <geometry>
        <mesh filename="../meshes/right_hand_thumb_rotaback_link1.STL" />
      </geometry>
      <material name="RAL_9003_Signal_White">
        <color rgba="0.941 0.941 0.941 1.0" />
      </material>
    </visual>
    <collision>
      <origin xyz="0 0 0" rpy="0 0 0" />
      <geometry>
        <mesh filename="../meshes/right_hand_thumb_rotaback_link1.STL" />
      </geometry>
    </collision>
  <inertial><origin xyz="0 0 0" rpy="0 0 0" /><mass value="0.01" /><inertia ixx="1e-5" iyy="1e-5" izz="1e-5" ixy="0" ixz="0" iyz="0" /></inertial></link>
  <joint name="right_hand_thumb_rotaback_joint1" type="fixed">
    <origin xyz="0.0553000000000007 0 0" rpy="0 0 0" />
    <parent link="right_hand_thumb_rota_link1" />
    <child link="right_hand_thumb_rotaback_link1" />
    <axis xyz="0 0 0" />
    <dynamics damping="0" friction="0" />
  </joint>
  <link name="right_hand_thumb_rota_link2">
    <inertial>
      <origin xyz="0.0225340009927979 -0.000881600697645881 -0.000614548321208525" rpy="0 0 0" />
      <mass value="0.04336091" />
      <inertia ixx="0.00000388" ixy="0.00000000001" ixz="0.00000015" iyy="0.00000902" iyz="-0.00000042" izz="0.00001046" />
    </inertial>
    <visual>
      <origin xyz="0 0 0" rpy="0 0 0" />
      <geometry>
        <mesh filename="../meshes/right_hand_thumb_rota_link2.STL" />
      </geometry>
      <material name="RAL_9005_Jet_Black">
        <color rgba="0.055 0.055 0.063 1.0" />
      </material>
    </visual>
    <collision>
      <origin xyz="0 0 0" rpy="0 0 0" />
      <geometry>
        <mesh filename="../meshes/right_hand_thumb_rota_link2.STL" />
      </geometry>
    </collision>
  </link>
  <joint name="right_hand_thumb_rota_joint2" type="revolute">
    <origin xyz="0.0553 0 0" rpy="0 0 0" />
    <parent link="right_hand_thumb_rota_link1" />
    <child link="right_hand_thumb_rota_link2" />
    <axis xyz="0 1 0" />
    <limit lower="0" upper="1.745" effort="0.4" velocity="14.38" />
    <dynamics damping="0" friction="0" />
  </joint>
  <link name="right_hand_thumb_rotaback_link2">
    <visual>
      <origin xyz="0 0 0" rpy="0 0 0" />
      <geometry>
        <mesh filename="../meshes/right_hand_thumb_rotaback_link2.STL" />
      </geometry>
      <material name="RAL_9003_Signal_White">
        <color rgba="0.941 0.941 0.941 1.0" />
      </material>
    </visual>
    <collision>
      <origin xyz="0 0 0" rpy="0 0 0" />
      <geometry>
        <mesh filename="../meshes/right_hand_thumb_rotaback_link2.STL" />
      </geometry>
    </collision>
  <inertial><origin xyz="0 0 0" rpy="0 0 0" /><mass value="0.01" /><inertia ixx="1e-5" iyy="1e-5" izz="1e-5" ixy="0" ixz="0" iyz="0" /></inertial></link>
  <joint name="right_hand_thumb_rotaback_joint2" type="fixed">
    <origin xyz="0.0502276499414862 0 0" rpy="0 0 0" />
    <parent link="right_hand_thumb_rota_link2" />
    <child link="right_hand_thumb_rotaback_link2" />
    <axis xyz="0 0 0" />
    <dynamics damping="0" friction="0" />
  </joint>
  <link name="right_hand_thumb_rota_tip">
    <visual>
      <origin xyz="0 0 0" rpy="0 0 0" />
      <geometry>
        <mesh filename="../meshes/right_hand_thumb_rota_tip.STL" />
      </geometry>
      <material name="RAL_9005_Jet_Black">
        <color rgba="0.055 0.055 0.063 1.0" />
      </material>
    </visual>
    <collision>
      <origin xyz="0 0 0" rpy="0 0 0" />
      <geometry>
        <mesh filename="../meshes/right_hand_thumb_rota_tip.STL" />
      </geometry>
    </collision>
  <inertial><origin xyz="0 0 0" rpy="0 0 0" /><mass value="0.01" /><inertia ixx="1e-5" iyy="1e-5" izz="1e-5" ixy="0" ixz="0" iyz="0" /></inertial></link>
  <joint name="right_hand_thumb_rota_joint3" type="fixed">
    <origin xyz="0.0502276499414862 0 0" rpy="0 0 0" />
    <parent link="right_hand_thumb_rota_link2" />
    <child link="right_hand_thumb_rota_tip" />
    <axis xyz="0 0 0" />
    <dynamics damping="0" friction="0" />
  </joint>
  <link name="right_hand_index_bend_link">
    <inertial>
      <origin xyz="0.000118997558760787 -0.000715851164577269 -0.0111903014853532" rpy="0 0 0" />
      <mass value="0.06910833" />
      <inertia ixx="0.0000174" ixy="0.00000001" ixz="0.00000014" iyy="0.00001677" iyz="-0.00000012" izz="0.00000345" />
    </inertial>
    <visual>
      <origin xyz="0 0 0" rpy="0 0 0" />
      <geometry>
        <mesh filename="../meshes/right_hand_index_bend_link.STL" />
      </geometry>
      <material name="RAL_9005_Jet_Black">
        <color rgba="0.055 0.055 0.063 1.0" />
      </material>
    </visual>
    <collision>
      <origin xyz="0 0 0" rpy="0 0 0" />
      <geometry>
        <mesh filename="../meshes/right_hand_index_bend_link.STL" />
      </geometry>
    </collision>
  </link>
  <joint name="right_hand_index_bend_joint" type="revolute">
    <origin xyz="0.0265 0.0065 -0.0899" rpy="0 0 0" />
    <parent link="right_hand_link" />
    <child link="right_hand_index_bend_link" />
    <axis xyz="0 -1 0" />
    <limit lower="-0.174" upper="0.174" effort="0.4" velocity="14.38" />
    <dynamics damping="0" friction="0" />
  </joint>
  <link name="right_hand_index_rota_link1">
    <inertial>
      <origin xyz="0.000133008106573459 0.000632930512954057 -0.0355868719939061" rpy="0 0 0" />
      <mass value="0.06298297" />
      <inertia ixx="0.00001738" ixy="0.00000000001" ixz="0.00000028" iyy="0.00001686" iyz="0.00000019" izz="0.0000032" />
    </inertial>
    <visual>
      <origin xyz="0 0 0" rpy="0 0 0" />
      <geometry>
        <mesh filename="../meshes/right_hand_index_rota_link1.STL" />
      </geometry>
      <material name="RAL_9005_Jet_Black">
        <color rgba="0.055 0.055 0.063 1" />
      </material>
    </visual>
    <collision>
      <origin xyz="0 0 0" rpy="0 0 0" />
      <geometry>
        <mesh filename="../meshes/right_hand_index_rota_link1.STL" />
      </geometry>
    </collision>
  </link>
  <joint name="right_hand_index_joint1" type="revolute">
    <origin xyz="0 0 -0.0178" rpy="0 0 0" />
    <parent link="right_hand_index_bend_link" />
    <child link="right_hand_index_rota_link1" />
    <axis xyz="1 0 0" />
    <limit lower="0" upper="1.919" effort="1.1" velocity="8.63" />
    <dynamics damping="0" friction="0" />
  </joint>
  <link name="right_hand_index_rotaback_link1">
    <visual>
      <origin xyz="0 0 0" rpy="0 0 0" />
      <geometry>
        <mesh filename="../meshes/right_hand_index_rotaback_link1.STL" />
      </geometry>
      <material name="RAL_9003_Signal_White">
        <color rgba="0.941 0.941 0.941 1" />
      </material>
    </visual>
    <collision>
      <origin xyz="0 0 0" rpy="0 0 0" />
      <geometry>
        <mesh filename="../meshes/right_hand_index_rotaback_link1.STL" />
      </geometry>
    </collision>
  <inertial><origin xyz="0 0 0" rpy="0 0 0" /><mass value="0.01" /><inertia ixx="1e-5" iyy="1e-5" izz="1e-5" ixy="0" ixz="0" iyz="0" /></inertial></link>
  <joint name="right_hand_index_rotaback_joint1" type="fixed">
    <origin xyz="0 0 -0.0557999999999955" rpy="0 0 0" />
    <parent link="right_hand_index_rota_link1" />
    <child link="right_hand_index_rotaback_link1" />
    <axis xyz="0 0 0" />
    <dynamics damping="0" friction="0" />
  </joint>
  <link name="right_hand_index_rota_link2">
    <inertial>
      <origin xyz="-0.000248361661985549 0.00119905190206764 -0.0213789854478675" rpy="0 0 0" />
      <mass value="0.01588724" />
      <inertia ixx="0.00000277" ixy="0.00000000001" ixz="0.00000012" iyy="0.00000283" iyz="0.00000007" izz="0.00000085" />
    </inertial>
    <visual>
      <origin xyz="0 0 0" rpy="0 0 0" />
      <geometry>
        <mesh filename="../meshes/right_hand_index_rota_link2.STL" />
      </geometry>
      <material name="RAL_9005_Jet_Black">
        <color rgba="0.055 0.055 0.063 1" />
      </material>
    </visual>
    <collision>
      <origin xyz="0 0 0" rpy="0 0 0" />
      <geometry>
        <mesh filename="../meshes/right_hand_index_rota_link2.STL" />
      </geometry>
    </collision>
  </link>
  <joint name="right_hand_index_joint2" type="revolute">
    <origin xyz="0 0 -0.0558" rpy="0 0 0" />
    <parent link="right_hand_index_rota_link1" />
    <child link="right_hand_index_rota_link2" />
    <axis xyz="1 0 0" />
    <limit lower="0" upper="1.919" effort="0.4" velocity="14.38" />
    <dynamics damping="0" friction="0" />
  </joint>
  <link name="right_hand_index_rotaback_link2">
    <visual>
      <origin xyz="0 0 0" rpy="0 0 0" />
      <geometry>
        <mesh filename="../meshes/right_hand_index_rotaback_link2.STL" />
      </geometry>
      <material name="RAL_9003_Signal_White">
        <color rgba="0.941 0.941 0.941 1" />
      </material>
    </visual>
    <collision>
      <origin xyz="0 0 0" rpy="0 0 0" />
      <geometry>
        <mesh filename="../meshes/right_hand_index_rotaback_link2.STL" />
      </geometry>
    </collision>
  <inertial><origin xyz="0 0 0" rpy="0 0 0" /><mass value="0.01" /><inertia ixx="1e-5" iyy="1e-5" izz="1e-5" ixy="0" ixz="0" iyz="0" /></inertial></link>
  <joint name="right_hand_index_rotaback_joint2" type="fixed">
    <origin xyz="0 0 -0.0422482924089416" rpy="0 0 0" />
    <parent link="right_hand_index_rota_link2" />
    <child link="right_hand_index_rotaback_link2" />
    <axis xyz="0 0 0" />
    <dynamics damping="0" friction="0" />
  </joint>
  <link name="right_hand_index_rota_tip">
    <visual>
      <origin xyz="0 0 0" rpy="0 0 0" />
      <geometry>
        <mesh filename="../meshes/right_hand_index_rota_tip.STL" />
      </geometry>
      <material name="RAL_9005_Jet_Black">
        <color rgba="0.055 0.055 0.063 1" />
      </material>
    </visual>
    <collision>
      <origin xyz="0 0 0" rpy="0 0 0" />
      <geometry>
        <mesh filename="../meshes/right_hand_index_rota_tip.STL" />
      </geometry>
    </collision>
  <inertial><origin xyz="0 0 0" rpy="0 0 0" /><mass value="0.01" /><inertia ixx="1e-5" iyy="1e-5" izz="1e-5" ixy="0" ixz="0" iyz="0" /></inertial></link>
  <joint name="right_hand_index_rota_joint3" type="fixed">
    <origin xyz="0 0 -0.0422482924089416" rpy="0 0 0" />
    <parent link="right_hand_index_rota_link2" />
    <child link="right_hand_index_rota_tip" />
    <axis xyz="0 0 0" />
    <dynamics damping="0" friction="0" />
  </joint>
  <link name="right_hand_mid_link1">
    <inertial>
      <origin xyz="3.58049083993136E-05 0.000530417592106078 -0.0332784671157236" rpy="0 0 0" />
      <mass value="0.06298297" />
      <inertia ixx="0.00001738" ixy="0.00000000001" ixz="0.00000028" iyy="0.00001686" iyz="0.00000019" izz="0.0000032" />
    </inertial>
    <visual>
      <origin xyz="0 0 0" rpy="0 0 0" />
      <geometry>
        <mesh filename="../meshes/right_hand_mid_link1.STL" />
      </geometry>
      <material name="RAL_9005_Jet_Black">
        <color rgba="0.055 0.055 0.063 1" />
      </material>
    </visual>
    <collision>
      <origin xyz="0 0 0" rpy="0 0 0" />
      <geometry>
        <mesh filename="../meshes/right_hand_mid_link1.STL" />
      </geometry>
    </collision>
  </link>
  <joint name="right_hand_mid_joint1" type="revolute">
    <origin xyz="0.004 0.0065 -0.1082" rpy="0 0 0" />
    <parent link="right_hand_link" />
    <child link="right_hand_mid_link1" />
    <axis xyz="1 0 0" />
    <limit lower="0" upper="1.919" effort="1.1" velocity="8.63" />
    <dynamics damping="0" friction="0" />
  </joint>
  <link name="right_hand_midback_link1">
    <visual>
      <origin xyz="0 0 0" rpy="0 0 0" />
      <geometry>
        <mesh filename="../meshes/right_hand_midback_link1.STL" />
      </geometry>
      <material name="RAL_9003_Signal_White">
        <color rgba="0.941 0.941 0.941 1" />
      </material>
    </visual>
    <collision>
      <origin xyz="0 0 0" rpy="0 0 0" />
      <geometry>
        <mesh filename="../meshes/right_hand_midback_link1.STL" />
      </geometry>
    </collision>
  <inertial><origin xyz="0 0 0" rpy="0 0 0" /><mass value="0.01" /><inertia ixx="1e-5" iyy="1e-5" izz="1e-5" ixy="0" ixz="0" iyz="0" /></inertial></link>
  <joint name="right_hand_midback_joint1" type="fixed">
    <origin xyz="0 0 -0.0558" rpy="0 0 0" />
    <parent link="right_hand_mid_link1" />
    <child link="right_hand_midback_link1" />
    <axis xyz="0 0 0" />
    <dynamics damping="0" friction="0" />
  </joint>
  <link name="right_hand_mid_link2">
    <inertial>
      <origin xyz="-0.000248364601983051 0.00119905076177324 -0.0213789908421273" rpy="0 0 0" />
      <mass value="0.01624108" />
      <inertia ixx="0.00000281" ixy="0.00000000001" ixz="0.00000012" iyy="0.00000287" iyz="0.00000007" izz="0.00000086" />
    </inertial>
    <visual>
      <origin xyz="0 0 0" rpy="0 0 0" />
      <geometry>
        <mesh filename="../meshes/right_hand_mid_link2.STL" />
      </geometry>
      <material name="RAL_9005_Jet_Black">
        <color rgba="0.055 0.055 0.063 1" />
      </material>
    </visual>
    <collision>
      <origin xyz="0 0 0" rpy="0 0 0" />
      <geometry>
        <mesh filename="../meshes/right_hand_mid_link2.STL" />
      </geometry>
    </collision>
  </link>
  <joint name="right_hand_mid_joint2" type="revolute">
    <origin xyz="0 0 -0.0558" rpy="0 0 0" />
    <parent link="right_hand_mid_link1" />
    <child link="right_hand_mid_link2" />
    <axis xyz="1 0 0" />
    <limit lower="0" upper="1.919" effort="0.4" velocity="14.38" />
    <dynamics damping="0" friction="0" />
  </joint>
  <link name="right_hand_midback_link2">
    <visual>
      <origin xyz="0 0 0" rpy="0 0 0" />
      <geometry>
        <mesh filename="../meshes/right_hand_midback_link2.STL" />
      </geometry>
      <material name="RAL_9003_Signal_White">
        <color rgba="0.941 0.941 0.941 1" />
      </material>
    </visual>
    <collision>
      <origin xyz="0 0 0" rpy="0 0 0" />
      <geometry>
        <mesh filename="../meshes/right_hand_midback_link2.STL" />
      </geometry>
    </collision>
  <inertial><origin xyz="0 0 0" rpy="0 0 0" /><mass value="0.01" /><inertia ixx="1e-5" iyy="1e-5" izz="1e-5" ixy="0" ixz="0" iyz="0" /></inertial></link>
  <joint name="right_hand_midback_joint2" type="fixed">
    <origin xyz="0 0 -0.042248" rpy="0 0 0" />
    <parent link="right_hand_mid_link2" />
    <child link="right_hand_midback_link2" />
    <axis xyz="0 0 0" />
    <dynamics damping="0" friction="0" />
  </joint>
  <link name="right_hand_mid_tip">
    <visual>
      <origin xyz="0 0 0" rpy="0 0 0" />
      <geometry>
        <mesh filename="../meshes/right_hand_mid_tip.STL" />
      </geometry>
      <material name="RAL_9005_Jet_Black">
        <color rgba="0.055 0.055 0.063 1" />
      </material>
    </visual>
    <collision>
      <origin xyz="0 0 0" rpy="0 0 0" />
      <geometry>
        <mesh filename="../meshes/right_hand_mid_tip.STL" />
      </geometry>
    </collision>
  <inertial><origin xyz="0 0 0" rpy="0 0 0" /><mass value="0.01" /><inertia ixx="1e-5" iyy="1e-5" izz="1e-5" ixy="0" ixz="0" iyz="0" /></inertial></link>
  <joint name="right_hand_mid_joint3" type="fixed">
    <origin xyz="0 0 -0.0422482924089417" rpy="0 0 0" />
    <parent link="right_hand_mid_link2" />
    <child link="right_hand_mid_tip" />
    <axis xyz="0 0 0" />
    <dynamics damping="0" friction="0" />
  </joint>
  <link name="right_hand_ring_link1">
    <inertial>
      <origin xyz="3.58049083615322E-05 0.000530417592105594 -0.0332784671157224" rpy="0 0 0" />
      <mass value="0.06298297" />
      <inertia ixx="0.00001738" ixy="0.00000000001" ixz="0.00000028" iyy="0.00001686" iyz="0.00000019" izz="0.0000032" />
    </inertial>
    <visual>
      <origin xyz="0 0 0" rpy="0 0 0" />
      <geometry>
        <mesh filename="../meshes/right_hand_ring_link1.STL" />
      </geometry>
      <material name="RAL_9005_Jet_Black">
        <color rgba="0.055 0.055 0.063 1" />
      </material>
    </visual>
    <collision>
      <origin xyz="0 0 0" rpy="0 0 0" />
      <geometry>
        <mesh filename="../meshes/right_hand_ring_link1.STL" />
      </geometry>
    </collision>
  </link>
  <joint name="right_hand_ring_joint1" type="revolute">
    <origin xyz="-0.016 0.0065 -0.1052" rpy="0 0 0" />
    <parent link="right_hand_link" />
    <child link="right_hand_ring_link1" />
    <axis xyz="1 0 0" />
    <limit lower="0" upper="1.919" effort="1.1" velocity="8.63" />
    <dynamics damping="0" friction="0" />
  </joint>
  <link name="right_hand_ringback_link1">
    <visual>
      <origin xyz="0 0 0" rpy="0 0 0" />
      <geometry>
        <mesh filename="../meshes/right_hand_ringback_link1.STL" />
      </geometry>
      <material name="RAL_9003_Signal_White">
        <color rgba="0.941 0.941 0.941 1" />
      </material>
    </visual>
    <collision>
      <origin xyz="0 0 0" rpy="0 0 0" />
      <geometry>
        <mesh filename="../meshes/right_hand_ringback_link1.STL" />
      </geometry>
    </collision>
  <inertial><origin xyz="0 0 0" rpy="0 0 0" /><mass value="0.01" /><inertia ixx="1e-5" iyy="1e-5" izz="1e-5" ixy="0" ixz="0" iyz="0" /></inertial></link>
  <joint name="right_hand_ringback_joint1" type="fixed">
    <origin xyz="0 0 -0.0558000000000002" rpy="0 0 0" />
    <parent link="right_hand_ring_link1" />
    <child link="right_hand_ringback_link1" />
    <axis xyz="0 0 0" />
    <dynamics damping="0" friction="0" />
  </joint>
  <link name="right_hand_ring_link2">
    <inertial>
      <origin xyz="-0.000248364602035429 0.00119905076177346 -0.0213789908421257" rpy="0 0 0" />
      <mass value="0.01624108" />
      <inertia ixx="0.00000281" ixy="0.00000000001" ixz="0.00000012" iyy="0.00000287" iyz="0.00000007" izz="0.00000086" />
    </inertial>
    <visual>
      <origin xyz="0 0 0" rpy="0 0 0" />
      <geometry>
        <mesh filename="../meshes/right_hand_ring_link2.STL" />
      </geometry>
      <material name="RAL_9005_Jet_Black">
        <color rgba="0.055 0.055 0.063 1" />
      </material>
    </visual>
    <collision>
      <origin xyz="0 0 0" rpy="0 0 0" />
      <geometry>
        <mesh filename="../meshes/right_hand_ring_link2.STL" />
      </geometry>
    </collision>
  </link>
  <joint name="right_hand_ring_joint2" type="revolute">
    <origin xyz="0 0 -0.0558" rpy="0 0 0" />
    <parent link="right_hand_ring_link1" />
    <child link="right_hand_ring_link2" />
    <axis xyz="1 0 0" />
    <limit lower="0" upper="1.919" effort="0.4" velocity="14.38" />
    <dynamics damping="0" friction="0" />
  </joint>
  <link name="right_hand_ringback_link2">
    <visual>
      <origin xyz="0 0 0" rpy="0 0 0" />
      <geometry>
        <mesh filename="../meshes/right_hand_ringback_link2.STL" />
      </geometry>
      <material name="RAL_9003_Signal_White">
        <color rgba="0.941 0.941 0.941 1" />
      </material>
    </visual>
    <collision>
      <origin xyz="0 0 0" rpy="0 0 0" />
      <geometry>
        <mesh filename="../meshes/right_hand_ringback_link2.STL" />
      </geometry>
    </collision>
  <inertial><origin xyz="0 0 0" rpy="0 0 0" /><mass value="0.01" /><inertia ixx="1e-5" iyy="1e-5" izz="1e-5" ixy="0" ixz="0" iyz="0" /></inertial></link>
  <joint name="right_hand_ringback_joint2" type="fixed">
    <origin xyz="0 0 -0.0422482924089403" rpy="0 0 0" />
    <parent link="right_hand_ring_link2" />
    <child link="right_hand_ringback_link2" />
    <axis xyz="0 0 0" />
    <dynamics damping="0" friction="0" />
  </joint>
  <link name="right_hand_ring_tip">
    <visual>
      <origin xyz="0 0 0" rpy="0 0 0" />
      <geometry>
        <mesh filename="../meshes/right_hand_ring_tip.STL" />
      </geometry>
      <material name="RAL_9005_Jet_Black">
        <color rgba="0.055 0.055 0.063 1" />
      </material>
    </visual>
    <collision>
      <origin xyz="0 0 0" rpy="0 0 0" />
      <geometry>
        <mesh filename="../meshes/right_hand_ring_tip.STL" />
      </geometry>
    </collision>
  <inertial><origin xyz="0 0 0" rpy="0 0 0" /><mass value="0.01" /><inertia ixx="1e-5" iyy="1e-5" izz="1e-5" ixy="0" ixz="0" iyz="0" /></inertial></link>
  <joint name="right_hand_ring_joint3" type="fixed">
    <origin xyz="0 0 -0.0422482924089403" rpy="0 0 0" />
    <parent link="right_hand_ring_link2" />
    <child link="right_hand_ring_tip" />
    <axis xyz="0 0 0" />
    <dynamics damping="0" friction="0" />
  </joint>
  <link name="right_hand_pinky_link1">
    <inertial>
      <origin xyz="3.58049083611298E-05 0.000530417592105422 -0.0332784671157224" rpy="0 0 0" />
      <mass value="0.06298297" />
      <inertia ixx="0.00001738" ixy="0.00000000001" ixz="0.00000028" iyy="0.00001686" iyz="0.00000019" izz="0.0000032" />
    </inertial>
    <visual>
      <origin xyz="0 0 0" rpy="0 0 0" />
      <geometry>
        <mesh filename="../meshes/right_hand_pinky_link1.STL" />
      </geometry>
      <material name="RAL_9005_Jet_Black">
        <color rgba="0.055 0.055 0.063 1" />
      </material>
    </visual>
    <collision>
      <origin xyz="0 0 0" rpy="0 0 0" />
      <geometry>
        <mesh filename="../meshes/right_hand_pinky_link1.STL" />
      </geometry>
    </collision>
  </link>
  <joint name="right_hand_pinky_joint1" type="revolute">
    <origin xyz="-0.036 0.0065 -0.1022" rpy="0 0 0" />
    <parent link="right_hand_link" />
    <child link="right_hand_pinky_link1" />
    <axis xyz="1 0 0" />
    <limit lower="0" upper="1.919" effort="1.1" velocity="8.63" />
    <dynamics damping="0" friction="0" />
  </joint>
  <link name="right_hand_pinkyback_link1">
    <visual>
      <origin xyz="0 0 0" rpy="0 0 0" />
      <geometry>
        <mesh filename="../meshes/right_hand_pinkyback_link1.STL" />
      </geometry>
      <material name="RAL_9003_Signal_White">
        <color rgba="0.941 0.941 0.941 1" />
      </material>
    </visual>
    <collision>
      <origin xyz="0 0 0" rpy="0 0 0" />
      <geometry>
        <mesh filename="../meshes/right_hand_pinkyback_link1.STL" />
      </geometry>
    </collision>
  <inertial><origin xyz="0 0 0" rpy="0 0 0" /><mass value="0.01" /><inertia ixx="1e-5" iyy="1e-5" izz="1e-5" ixy="0" ixz="0" iyz="0" /></inertial></link>
  <joint name="right_hand_pinkyback_joint1" type="fixed">
    <origin xyz="0 0 -0.0558000000000001" rpy="0 0 0" />
    <parent link="right_hand_pinky_link1" />
    <child link="right_hand_pinkyback_link1" />
    <axis xyz="0 0 0" />
    <dynamics damping="0" friction="0" />
  </joint>
  <link name="right_hand_pinky_link2">
    <inertial>
      <origin xyz="-0.000248361662015334 0.0011990519020671 -0.0213789854478658" rpy="0 0 0" />
      <mass value="0.01624108" />
      <inertia ixx="0.00000281" ixy="0.00000000001" ixz="0.00000012" iyy="0.00000287" iyz="0.00000007" izz="0.00000086" />
    </inertial>
    <visual>
      <origin xyz="0 0 0" rpy="0 0 0" />
      <geometry>
        <mesh filename="../meshes/right_hand_pinky_link2.STL" />
      </geometry>
      <material name="RAL_9005_Jet_Black">
        <color rgba="0.055 0.055 0.063 1" />
      </material>
    </visual>
    <collision>
      <origin xyz="0 0 0" rpy="0 0 0" />
      <geometry>
        <mesh filename="../meshes/right_hand_pinky_link2.STL" />
      </geometry>
    </collision>
  </link>
  <joint name="right_hand_pinky_joint2" type="revolute">
    <origin xyz="0 0 -0.0558" rpy="0 0 0" />
    <parent link="right_hand_pinky_link1" />
    <child link="right_hand_pinky_link2" />
    <axis xyz="1 0 0" />
    <limit lower="0" upper="1.919" effort="1.4" velocity="14.38" />
    <dynamics damping="0" friction="0" />
  </joint>
  <link name="right_hand_pinkyback_link2">
    <visual>
      <origin xyz="0 0 0" rpy="0 0 0" />
      <geometry>
        <mesh filename="../meshes/right_hand_pinkyback_link2.STL" />
      </geometry>
      <material name="RAL_9003_Signal_White">
        <color rgba="0.941 0.941 0.941 1" />
      </material>
    </visual>
    <collision>
      <origin xyz="0 0 0" rpy="0 0 0" />
      <geometry>
        <mesh filename="../meshes/right_hand_pinkyback_link2.STL" />
      </geometry>
    </collision>
  <inertial><origin xyz="0 0 0" rpy="0 0 0" /><mass value="0.01" /><inertia ixx="1e-5" iyy="1e-5" izz="1e-5" ixy="0" ixz="0" iyz="0" /></inertial></link>
  <joint name="right_hand_pinkyback_joint2" type="fixed">
    <origin xyz="0 0 -0.0422482924089404" rpy="0 0 0" />
    <parent link="right_hand_pinky_link2" />
    <child link="right_hand_pinkyback_link2" />
    <axis xyz="0 0 0" />
    <dynamics damping="0" friction="0" />
  </joint>
  <link name="right_hand_pinky_tip">
    <visual>
      <origin xyz="0 0 0" rpy="0 0 0" />
      <geometry>
        <mesh filename="../meshes/right_hand_pinky_tip.STL" />
      </geometry>
      <material name="RAL_9005_Jet_Black">
        <color rgba="0.055 0.055 0.063 1" />
      </material>
    </visual>
    <collision>
      <origin xyz="0 0 0" rpy="0 0 0" />
      <geometry>
        <mesh filename="../meshes/right_hand_pinky_tip.STL" />
      </geometry>
    </collision>
  <inertial><origin xyz="0 0 0" rpy="0 0 0" /><mass value="0.01" /><inertia ixx="1e-5" iyy="1e-5" izz="1e-5" ixy="0" ixz="0" iyz="0" /></inertial></link>
  <joint name="right_hand_pinky_joint3" type="fixed">
    <origin xyz="0 0 -0.0422482924089404" rpy="0 0 0" />
    <parent link="right_hand_pinky_link2" />
    <child link="right_hand_pinky_tip" />
    <axis xyz="0 0 0" />
    <dynamics damping="0" friction="0" />
  </joint>
</robot>